{"trial_id": "00", "hyperparameters": {"space": [{"class_name": "Int", "config": {"name": "n_lstm_units", "default": null, "conditions": [], "min_value": 64, "max_value": 256, "step": 32, "sampling": "linear"}}, {"class_name": "Int", "config": {"name": "n_elm_neurons", "default": null, "conditions": [], "min_value": 64, "max_value": 256, "step": 32, "sampling": "linear"}}, {"class_name": "Choice", "config": {"name": "activation", "default": "sigmoid", "conditions": [], "values": ["sigmoid", "tanh"], "ordered": false}}], "values": {"n_lstm_units": 96, "n_elm_neurons": 224, "activation": "sigmoid"}}, "metrics": {"metrics": {}}, "score": null, "best_step": 0, "status": "FAILED", "message": "Traceback (most recent call last):\n  File \"c:\\Users\\LAPTOP WORLD\\AppData\\Local\\Programs\\Python\\Python39\\lib\\site-packages\\keras_tuner\\engine\\base_tuner.py\", line 270, in _try_run_and_update_trial\n    self._run_and_update_trial(trial, *fit_args, **fit_kwargs)\n  File \"c:\\Users\\LAPTOP WORLD\\AppData\\Local\\Programs\\Python\\Python39\\lib\\site-packages\\keras_tuner\\engine\\base_tuner.py\", line 235, in _run_and_update_trial\n    results = self.run_trial(trial, *fit_args, **fit_kwargs)\n  File \"c:\\Users\\LAPTOP WORLD\\AppData\\Local\\Programs\\Python\\Python39\\lib\\site-packages\\keras_tuner\\engine\\tuner.py\", line 287, in run_trial\n    obj_value = self._build_and_fit_model(trial, *args, **copied_kwargs)\n  File \"c:\\Users\\LAPTOP WORLD\\AppData\\Local\\Programs\\Python\\Python39\\lib\\site-packages\\keras_tuner\\engine\\tuner.py\", line 214, in _build_and_fit_model\n    results = self.hypermodel.fit(hp, model, *args, **kwargs)\n  File \"c:\\Users\\LAPTOP WORLD\\AppData\\Local\\Programs\\Python\\Python39\\lib\\site-packages\\keras_tuner\\engine\\hypermodel.py\", line 144, in fit\n    return model.fit(*args, **kwargs)\n  File \"c:\\Users\\LAPTOP WORLD\\AppData\\Local\\Programs\\Python\\Python39\\lib\\site-packages\\keras\\utils\\traceback_utils.py\", line 70, in error_handler\n    raise e.with_traceback(filtered_tb) from None\n  File \"C:\\Users\\LAPTOP~1\\AppData\\Local\\Temp\\__autograph_generated_file6jsqh0v1.py\", line 15, in tf__train_function\n    retval_ = ag__.converted_call(ag__.ld(step_function), (ag__.ld(self), ag__.ld(iterator)), None, fscope)\nValueError: in user code:\n\n    File \"c:\\Users\\LAPTOP WORLD\\AppData\\Local\\Programs\\Python\\Python39\\lib\\site-packages\\keras\\engine\\training.py\", line 1249, in train_function  *\n        return step_function(self, iterator)\n    File \"c:\\Users\\LAPTOP WORLD\\AppData\\Local\\Programs\\Python\\Python39\\lib\\site-packages\\keras\\engine\\training.py\", line 1233, in step_function  **\n        outputs = model.distribute_strategy.run(run_step, args=(data,))\n    File \"c:\\Users\\LAPTOP WORLD\\AppData\\Local\\Programs\\Python\\Python39\\lib\\site-packages\\keras\\engine\\training.py\", line 1222, in run_step  **\n        outputs = model.train_step(data)\n    File \"c:\\Users\\LAPTOP WORLD\\AppData\\Local\\Programs\\Python\\Python39\\lib\\site-packages\\keras\\engine\\training.py\", line 1023, in train_step\n        y_pred = self(x, training=True)\n    File \"c:\\Users\\LAPTOP WORLD\\AppData\\Local\\Programs\\Python\\Python39\\lib\\site-packages\\keras\\utils\\traceback_utils.py\", line 70, in error_handler\n        raise e.with_traceback(filtered_tb) from None\n    File \"c:\\Users\\LAPTOP WORLD\\AppData\\Local\\Programs\\Python\\Python39\\lib\\site-packages\\keras\\engine\\input_spec.py\", line 295, in assert_input_compatibility\n        raise ValueError(\n\n    ValueError: Input 0 of layer \"sequential\" is incompatible with the layer: expected shape=(None, 6111, 12), found shape=(None, 12)\n\n"}